<?xml version="1.0" encoding="utf-8"?>
<!-- This URDF was automatically created by SolidWorks to URDF Exporter! Originally created by Stephen Brawner (brawner@gmail.com) 
     Commit Version: 1.5.1-0-g916b5db  Build Version: 1.5.7152.31018
     For more information, please see http://wiki.ros.org/sw_urdf_exporter -->
<robot
  name="Aragog URDF part 2">
  <link
    name="base_link">
    <inertial>
      <origin
        xyz="0.0172950290306701 0.0195586474806615 0.0358952518160799"
        rpy="0 0 0" />
      <mass
        value="0.03170249194558" />
      <inertia
        ixx="5.57716796288184E-06"
        ixy="-2.9814567560052E-08"
        ixz="-1.45978738176302E-11"
        iyy="2.87877286112393E-06"
        iyz="1.86969467308466E-11"
        izz="4.09670113187748E-06" />
    </inertial>
    <visual>
      <origin
        xyz="0 0 0"
        rpy="0 0 0" />
      <geometry>
        <mesh
          filename="package://Aragog URDF part 2/meshes/base_link.STL" />
      </geometry>
      <material
        name="">
        <color
          rgba="0.792156862745098 0.819607843137255 0.933333333333333 1" />
      </material>
    </visual>
    <collision>
      <origin
        xyz="0 0 0"
        rpy="0 0 0" />
      <geometry>
        <mesh
          filename="package://Aragog URDF part 2/meshes/base_link.STL" />
      </geometry>
    </collision>
  </link>
  <link
    name="right_leg">
    <inertial>
      <origin
        xyz="0.022665 -0.024691 1.5767E-10"
        rpy="0 0 0" />
      <mass
        value="0.0099613" />
      <inertia
        ixx="2.4922E-06"
        ixy="-6.5075E-07"
        ixz="-3.703E-13"
        iyy="4.5337E-06"
        iyz="1.1197E-13"
        izz="3.1192E-06" />
    </inertial>
    <visual>
      <origin
        xyz="0 0 0"
        rpy="0 0 0" />
      <geometry>
        <mesh
          filename="package://Aragog URDF part 2/meshes/right_leg.STL" />
      </geometry>
      <material
        name="">
        <color
          rgba="0.79216 0.81961 0.93333 1" />
      </material>
    </visual>
    <collision>
      <origin
        xyz="0 0 0"
        rpy="0 0 0" />
      <geometry>
        <mesh
          filename="package://Aragog URDF part 2/meshes/right_leg.STL" />
      </geometry>
    </collision>
  </link>
  <joint
    name="right_revolute"
    type="revolute">
    <origin
      xyz="0 -0.019795 0.02572"
      rpy="3.1337 0 0" />
    <parent
      link="base_link" />
    <child
      link="right_leg" />
    <axis
      xyz="1 0 0" />
    <limit
      lower="0"
      upper="2"
      effort="0"
      velocity="0" />
  </joint>
  <link
    name="middle_leg">
    <inertial>
      <origin
        xyz="-0.0015 -0.0086543 -2.4286E-16"
        rpy="0 0 0" />
      <mass
        value="0.0064836" />
      <inertia
        ixx="1.099E-05"
        ixy="1.0732E-22"
        ixz="-8.2747E-22"
        iyy="8.1223E-06"
        iyz="5.3734E-21"
        izz="2.8777E-06" />
    </inertial>
    <visual>
      <origin
        xyz="0 0 0"
        rpy="0 0 0" />
      <geometry>
        <mesh
          filename="package://Aragog URDF part 2/meshes/middle_leg.STL" />
      </geometry>
      <material
        name="">
        <color
          rgba="0.79216 0.81961 0.93333 1" />
      </material>
    </visual>
    <collision>
      <origin
        xyz="0 0 0"
        rpy="0 0 0" />
      <geometry>
        <mesh
          filename="package://Aragog URDF part 2/meshes/middle_leg.STL" />
      </geometry>
    </collision>
  </link>
  <joint
    name="middle_revolute"
    type="revolute">
    <origin
      xyz="0.036131 -0.035895 0.02927"
      rpy="1.4239 1.5708 0" />
    <parent
      link="base_link" />
    <child
      link="middle_leg" />
    <axis
      xyz="1 0 0" />
    <limit
      lower="0"
      upper="2"
      effort="0"
      velocity="0" />
  </joint>
  <link
    name="left_leg">
    <inertial>
      <origin
        xyz="0.022665 -0.024691 -7.3476E-11"
        rpy="0 0 0" />
      <mass
        value="0.0099613" />
      <inertia
        ixx="2.4922E-06"
        ixy="-6.5075E-07"
        ixz="-3.6991E-13"
        iyy="4.5337E-06"
        iyz="1.1871E-13"
        izz="3.1192E-06" />
    </inertial>
    <visual>
      <origin
        xyz="0 0 0"
        rpy="0 0 0" />
      <geometry>
        <mesh
          filename="package://Aragog URDF part 2/meshes/left_leg.STL" />
      </geometry>
      <material
        name="">
        <color
          rgba="0.79216 0.81961 0.93333 1" />
      </material>
    </visual>
    <collision>
      <origin
        xyz="0 0 0"
        rpy="0 0 0" />
      <geometry>
        <mesh
          filename="package://Aragog URDF part 2/meshes/left_leg.STL" />
      </geometry>
    </collision>
  </link>
  <joint
    name="left_revolute"
    type="revolute">
    <origin
      xyz="0 -0.051995 0.02572"
      rpy="0.0087503 0 0" />
    <parent
      link="base_link" />
    <child
      link="left_leg" />
    <axis
      xyz="1 0 0" />
    <limit
      lower="0"
      upper="2"
      effort="0"
      velocity="0" />
  </joint>
</robot>